2017-12-01 18:02:42  [success] success to check_shell success from 172.17.0.4:80 with the script:function.py check_shell
2017-12-01 18:02:42  [success] success to execution cmd from 172.17.0.4:80 with the script:sample.py
2017-12-01 18:02:42  [warning] fail to attack: 118.190.78.155:80 with error: check_shell failed with the script: function.py check_shell
2017-12-01 18:02:42  [warning] fail to attack: 118.190.78.155:80 with error: execution cmd failed with the script: sample.py
2017-12-01 18:03:01  [success] success to check_shell success from 172.17.0.4:80 with the script:function.py check_shell
2017-12-01 18:03:01  [success] success to execution cmd from 172.17.0.4:80 with the script:sample.py
2017-12-01 18:03:01  [warning] fail to attack: 118.190.78.155:80 with error: check_shell failed with the script: function.py check_shell
2017-12-01 18:03:01  [warning] fail to attack: 118.190.78.155:80 with error: execution cmd failed with the script: sample.py
2017-12-01 18:03:04  [success] success to check_shell success from 172.17.0.4:80 with the script:function.py check_shell
2017-12-01 18:03:04  [success] success to execution cmd from 172.17.0.4:80 with the script:sample.py
2017-12-01 18:03:04  [warning] fail to attack: 118.190.78.155:80 with error: check_shell failed with the script: function.py check_shell
2017-12-01 18:03:04  [warning] fail to attack: 118.190.78.155:80 with error: execution cmd failed with the script: sample.py
2017-12-01 18:03:07  [success] success to check_shell success from 172.17.0.4:80 with the script:function.py check_shell
2017-12-01 18:03:07  [success] success to execution cmd from 172.17.0.4:80 with the script:sample.py
2017-12-01 18:03:07  [warning] fail to attack: 118.190.78.155:80 with error: check_shell failed with the script: function.py check_shell
2017-12-01 18:03:08  [warning] fail to attack: 118.190.78.155:80 with error: execution cmd failed with the script: sample.py
2017-12-01 18:03:11  [success] success to check_shell success from 172.17.0.4:80 with the script:function.py check_shell
2017-12-01 18:03:11  [success] success to execution cmd from 172.17.0.4:80 with the script:sample.py
2017-12-01 18:03:11  [warning] fail to attack: 118.190.78.155:80 with error: check_shell failed with the script: function.py check_shell
2017-12-01 18:03:11  [warning] fail to attack: 118.190.78.155:80 with error: execution cmd failed with the script: sample.py
2017-12-01 18:03:14  [success] success to check_shell success from 172.17.0.4:80 with the script:function.py check_shell
2017-12-01 18:03:14  [success] success to execution cmd from 172.17.0.4:80 with the script:sample.py
2017-12-01 18:03:14  [warning] fail to attack: 118.190.78.155:80 with error: check_shell failed with the script: function.py check_shell
2017-12-01 18:03:14  [warning] fail to attack: 118.190.78.155:80 with error: execution cmd failed with the script: sample.py
2017-12-01 18:03:17  [success] success to check_shell success from 172.17.0.4:80 with the script:function.py check_shell
2017-12-01 18:03:17  [success] success to execution cmd from 172.17.0.4:80 with the script:sample.py
2017-12-01 18:03:18  [warning] fail to attack: 118.190.78.155:80 with error: check_shell failed with the script: function.py check_shell
2017-12-01 18:03:18  [warning] fail to attack: 118.190.78.155:80 with error: execution cmd failed with the script: sample.py
2017-12-01 18:03:43  [success] success to check_shell success from 172.17.0.4:80 with the script:function.py check_shell
2017-12-01 18:03:43  [success] success to execution cmd from 172.17.0.4:80 with the script:sample.py
2017-12-01 18:03:44  [warning] fail to attack: 118.190.78.155:80 with error: check_shell failed with the script: function.py check_shell
2017-12-01 18:03:44  [warning] fail to attack: 118.190.78.155:80 with error: execution cmd failed with the script: sample.py
2017-12-01 18:03:46  [error] fail to attack: 8.8.8.8 with error: HTTPConnectionPool(host='8.8.8.8', port=80): Max retries exceeded with url: /Uploads//.ad185973674f3bc1f3f8548e4bb5089b.php (Caused by ConnectTimeoutError(<requests.packages.urllib3.connection.HTTPConnection object at 0x7fda0a3a3410>, 'Connection to 8.8.8.8 timed out. (connect timeout=2)')) with the script: sample
2017-12-01 18:03:48  [error] fail to attack: 1.121.1.222 with error: HTTPConnectionPool(host='1.121.1.222', port=81): Max retries exceeded with url: /Uploads//.7b07e07c3769f27d0ff6fc43abac61c3.php (Caused by ConnectTimeoutError(<requests.packages.urllib3.connection.HTTPConnection object at 0x7fda0a375290>, 'Connection to 1.121.1.222 timed out. (connect timeout=2)')) with the script: sample
2017-12-01 18:03:51  [success] success to check_shell success from 172.17.0.4:80 with the script:function.py check_shell
2017-12-01 18:03:51  [success] success to execution cmd from 172.17.0.4:80 with the script:sample.py
2017-12-01 18:03:51  [warning] fail to attack: 118.190.78.155:80 with error: check_shell failed with the script: function.py check_shell
2017-12-01 18:03:51  [warning] fail to attack: 118.190.78.155:80 with error: execution cmd failed with the script: sample.py
2017-12-01 18:03:53  [error] fail to attack: 8.8.8.8 with error: HTTPConnectionPool(host='8.8.8.8', port=80): Max retries exceeded with url: /Uploads//.ad185973674f3bc1f3f8548e4bb5089b.php (Caused by ConnectTimeoutError(<requests.packages.urllib3.connection.HTTPConnection object at 0x7fda0a38b850>, 'Connection to 8.8.8.8 timed out. (connect timeout=2)')) with the script: sample
2017-12-01 18:03:55  [error] fail to attack: 1.121.1.222 with error: HTTPConnectionPool(host='1.121.1.222', port=81): Max retries exceeded with url: /Uploads//.7b07e07c3769f27d0ff6fc43abac61c3.php (Caused by ConnectTimeoutError(<requests.packages.urllib3.connection.HTTPConnection object at 0x7fda0a375310>, 'Connection to 1.121.1.222 timed out. (connect timeout=2)')) with the script: sample
2017-12-01 18:03:58  [success] success to check_shell success from 172.17.0.4:80 with the script:function.py check_shell
2017-12-01 18:03:58  [success] success to execution cmd from 172.17.0.4:80 with the script:sample.py
2017-12-01 18:03:58  [warning] fail to attack: 118.190.78.155:80 with error: check_shell failed with the script: function.py check_shell
2017-12-01 18:03:59  [warning] fail to attack: 118.190.78.155:80 with error: execution cmd failed with the script: sample.py
2017-12-01 18:04:01  [error] fail to attack: 8.8.8.8 with error: HTTPConnectionPool(host='8.8.8.8', port=80): Max retries exceeded with url: /Uploads//.ad185973674f3bc1f3f8548e4bb5089b.php (Caused by ConnectTimeoutError(<requests.packages.urllib3.connection.HTTPConnection object at 0x7fda0a38b810>, 'Connection to 8.8.8.8 timed out. (connect timeout=2)')) with the script: sample
2017-12-01 18:04:03  [error] fail to attack: 1.121.1.222 with error: HTTPConnectionPool(host='1.121.1.222', port=81): Max retries exceeded with url: /Uploads//.7b07e07c3769f27d0ff6fc43abac61c3.php (Caused by ConnectTimeoutError(<requests.packages.urllib3.connection.HTTPConnection object at 0x7fda0a375350>, 'Connection to 1.121.1.222 timed out. (connect timeout=2)')) with the script: sample
2017-12-01 18:04:06  [success] success to check_shell success from 172.17.0.4:80 with the script:function.py check_shell
2017-12-01 18:04:06  [success] success to execution cmd from 172.17.0.4:80 with the script:sample.py
2017-12-01 18:04:06  [warning] fail to attack: 118.190.78.155:80 with error: check_shell failed with the script: function.py check_shell
2017-12-01 18:04:06  [warning] fail to attack: 118.190.78.155:80 with error: execution cmd failed with the script: sample.py
2017-12-01 18:04:08  [error] fail to attack: 8.8.8.8 with error: HTTPConnectionPool(host='8.8.8.8', port=80): Max retries exceeded with url: /Uploads//.ad185973674f3bc1f3f8548e4bb5089b.php (Caused by ConnectTimeoutError(<requests.packages.urllib3.connection.HTTPConnection object at 0x7fda0a36aa90>, 'Connection to 8.8.8.8 timed out. (connect timeout=2)')) with the script: sample
2017-12-01 18:04:10  [error] fail to attack: 1.121.1.222 with error: HTTPConnectionPool(host='1.121.1.222', port=81): Max retries exceeded with url: /Uploads//.7b07e07c3769f27d0ff6fc43abac61c3.php (Caused by ConnectTimeoutError(<requests.packages.urllib3.connection.HTTPConnection object at 0x7fda0a3753d0>, 'Connection to 1.121.1.222 timed out. (connect timeout=2)')) with the script: sample
2017-12-01 18:04:13  [success] success to check_shell success from 172.17.0.4:80 with the script:function.py check_shell
2017-12-01 18:04:13  [success] success to execution cmd from 172.17.0.4:80 with the script:sample.py
2017-12-01 18:04:13  [warning] fail to attack: 118.190.78.155:80 with error: check_shell failed with the script: function.py check_shell
2017-12-01 18:04:13  [warning] fail to attack: 118.190.78.155:80 with error: execution cmd failed with the script: sample.py
2017-12-01 18:04:15  [error] fail to attack: 8.8.8.8 with error: HTTPConnectionPool(host='8.8.8.8', port=80): Max retries exceeded with url: /Uploads//.ad185973674f3bc1f3f8548e4bb5089b.php (Caused by ConnectTimeoutError(<requests.packages.urllib3.connection.HTTPConnection object at 0x7fda0a36ab10>, 'Connection to 8.8.8.8 timed out. (connect timeout=2)')) with the script: sample
2017-12-01 18:04:17  [error] fail to attack: 1.121.1.222 with error: HTTPConnectionPool(host='1.121.1.222', port=81): Max retries exceeded with url: /Uploads//.7b07e07c3769f27d0ff6fc43abac61c3.php (Caused by ConnectTimeoutError(<requests.packages.urllib3.connection.HTTPConnection object at 0x7fda0a375450>, 'Connection to 1.121.1.222 timed out. (connect timeout=2)')) with the script: sample
2017-12-01 18:04:20  [success] success to check_shell success from 172.17.0.4:80 with the script:function.py check_shell
2017-12-01 18:04:20  [success] success to execution cmd from 172.17.0.4:80 with the script:sample.py
2017-12-01 18:04:21  [warning] fail to attack: 118.190.78.155:80 with error: check_shell failed with the script: function.py check_shell
2017-12-01 18:04:21  [warning] fail to attack: 118.190.78.155:80 with error: execution cmd failed with the script: sample.py
2017-12-01 18:04:23  [error] fail to attack: 8.8.8.8 with error: HTTPConnectionPool(host='8.8.8.8', port=80): Max retries exceeded with url: /Uploads//.ad185973674f3bc1f3f8548e4bb5089b.php (Caused by ConnectTimeoutError(<requests.packages.urllib3.connection.HTTPConnection object at 0x7fda0a36ac90>, 'Connection to 8.8.8.8 timed out. (connect timeout=2)')) with the script: sample
2017-12-01 18:04:25  [error] fail to attack: 1.121.1.222 with error: HTTPConnectionPool(host='1.121.1.222', port=81): Max retries exceeded with url: /Uploads//.7b07e07c3769f27d0ff6fc43abac61c3.php (Caused by ConnectTimeoutError(<requests.packages.urllib3.connection.HTTPConnection object at 0x7fda0a3754d0>, 'Connection to 1.121.1.222 timed out. (connect timeout=2)')) with the script: sample
2017-12-01 18:04:28  [success] success to check_shell success from 172.17.0.4:80 with the script:function.py check_shell
2017-12-01 18:04:28  [success] success to execution cmd from 172.17.0.4:80 with the script:sample.py
2017-12-01 18:04:28  [warning] fail to attack: 118.190.78.155:80 with error: check_shell failed with the script: function.py check_shell
2017-12-01 18:04:28  [warning] fail to attack: 118.190.78.155:80 with error: execution cmd failed with the script: sample.py
2017-12-01 18:04:30  [error] fail to attack: 8.8.8.8 with error: HTTPConnectionPool(host='8.8.8.8', port=80): Max retries exceeded with url: /Uploads//.ad185973674f3bc1f3f8548e4bb5089b.php (Caused by ConnectTimeoutError(<requests.packages.urllib3.connection.HTTPConnection object at 0x7fda0a36ab10>, 'Connection to 8.8.8.8 timed out. (connect timeout=2)')) with the script: sample
2017-12-01 18:04:32  [error] fail to attack: 1.121.1.222 with error: HTTPConnectionPool(host='1.121.1.222', port=81): Max retries exceeded with url: /Uploads//.7b07e07c3769f27d0ff6fc43abac61c3.php (Caused by ConnectTimeoutError(<requests.packages.urllib3.connection.HTTPConnection object at 0x7fda0a375550>, 'Connection to 1.121.1.222 timed out. (connect timeout=2)')) with the script: sample
2017-12-01 18:04:35  [success] success to check_shell success from 172.17.0.4:80 with the script:function.py check_shell
2017-12-01 18:04:35  [success] success to execution cmd from 172.17.0.4:80 with the script:sample.py
2017-12-01 18:04:35  [warning] fail to attack: 118.190.78.155:80 with error: check_shell failed with the script: function.py check_shell
2017-12-01 18:04:36  [warning] fail to attack: 118.190.78.155:80 with error: execution cmd failed with the script: sample.py
2017-12-01 18:04:38  [error] fail to attack: 8.8.8.8 with error: HTTPConnectionPool(host='8.8.8.8', port=80): Max retries exceeded with url: /Uploads//.ad185973674f3bc1f3f8548e4bb5089b.php (Caused by ConnectTimeoutError(<requests.packages.urllib3.connection.HTTPConnection object at 0x7fda0a36ac90>, 'Connection to 8.8.8.8 timed out. (connect timeout=2)')) with the script: sample
2017-12-01 18:04:40  [error] fail to attack: 1.121.1.222 with error: HTTPConnectionPool(host='1.121.1.222', port=81): Max retries exceeded with url: /Uploads//.7b07e07c3769f27d0ff6fc43abac61c3.php (Caused by ConnectTimeoutError(<requests.packages.urllib3.connection.HTTPConnection object at 0x7fda0a3755d0>, 'Connection to 1.121.1.222 timed out. (connect timeout=2)')) with the script: sample
2017-12-01 18:04:43  [success] success to check_shell success from 172.17.0.4:80 with the script:function.py check_shell
2017-12-01 18:04:43  [success] success to execution cmd from 172.17.0.4:80 with the script:sample.py
2017-12-01 18:04:43  [warning] fail to attack: 118.190.78.155:80 with error: check_shell failed with the script: function.py check_shell
2017-12-01 18:04:43  [warning] fail to attack: 118.190.78.155:80 with error: execution cmd failed with the script: sample.py
2017-12-01 18:04:45  [error] fail to attack: 8.8.8.8 with error: HTTPConnectionPool(host='8.8.8.8', port=80): Max retries exceeded with url: /Uploads//.ad185973674f3bc1f3f8548e4bb5089b.php (Caused by ConnectTimeoutError(<requests.packages.urllib3.connection.HTTPConnection object at 0x7fda0a36ac90>, 'Connection to 8.8.8.8 timed out. (connect timeout=2)')) with the script: sample
2017-12-01 18:04:47  [error] fail to attack: 1.121.1.222 with error: HTTPConnectionPool(host='1.121.1.222', port=81): Max retries exceeded with url: /Uploads//.7b07e07c3769f27d0ff6fc43abac61c3.php (Caused by ConnectTimeoutError(<requests.packages.urllib3.connection.HTTPConnection object at 0x7fda0a375650>, 'Connection to 1.121.1.222 timed out. (connect timeout=2)')) with the script: sample
2017-12-01 18:05:19  [success] success to check_shell success from 172.17.0.4:80 with the script:function.py check_shell
2017-12-01 18:05:19  [success] success to execution cmd from 172.17.0.4:80 with the script:sample.py
2017-12-01 18:05:19  [warning] fail to attack: 118.190.78.155:80 with error: check_shell failed with the script: function.py check_shell
2017-12-01 18:05:20  [warning] fail to attack: 118.190.78.155:80 with error: execution cmd failed with the script: sample.py
2017-12-01 18:05:22  [error] fail to attack: 8.8.8.8 with error: HTTPConnectionPool(host='8.8.8.8', port=80): Max retries exceeded with url: /Uploads//.ad185973674f3bc1f3f8548e4bb5089b.php (Caused by ConnectTimeoutError(<requests.packages.urllib3.connection.HTTPConnection object at 0x7fbdf7163410>, 'Connection to 8.8.8.8 timed out. (connect timeout=2)')) with the script: sample
2017-12-01 18:05:41  [success] success to check_shell success from 172.17.0.4:80 with the script:function.py check_shell
2017-12-01 18:05:41  [success] success to execution cmd from 172.17.0.4:80 with the script:sample.py
2017-12-01 18:05:41  [warning] fail to attack: 118.190.78.155:80 with error: check_shell failed with the script: function.py check_shell
2017-12-01 18:05:41  [warning] fail to attack: 118.190.78.155:80 with error: execution cmd failed with the script: sample.py
2017-12-01 18:05:43  [error] fail to attack: 8.8.8.8 with error: HTTPConnectionPool(host='8.8.8.8', port=80): Max retries exceeded with url: /Uploads//.ad185973674f3bc1f3f8548e4bb5089b.php (Caused by ConnectTimeoutError(<requests.packages.urllib3.connection.HTTPConnection object at 0x7f93814f5410>, 'Connection to 8.8.8.8 timed out. (connect timeout=2)')) with the script: sample
2017-12-01 18:05:45  [error] fail to attack: 1.121.1.222 with error: HTTPConnectionPool(host='1.121.1.222', port=81): Max retries exceeded with url: /Uploads//.7b07e07c3769f27d0ff6fc43abac61c3.php (Caused by ConnectTimeoutError(<requests.packages.urllib3.connection.HTTPConnection object at 0x7f93814c7290>, 'Connection to 1.121.1.222 timed out. (connect timeout=2)')) with the script: sample
2017-12-01 18:05:48  [success] success to check_shell success from 172.17.0.4:80 with the script:function.py check_shell
2017-12-01 18:05:48  [success] success to execution cmd from 172.17.0.4:80 with the script:sample.py
2017-12-01 18:05:48  [warning] fail to attack: 118.190.78.155:80 with error: check_shell failed with the script: function.py check_shell
2017-12-01 18:05:48  [warning] fail to attack: 118.190.78.155:80 with error: execution cmd failed with the script: sample.py
2017-12-01 18:05:50  [error] fail to attack: 8.8.8.8 with error: HTTPConnectionPool(host='8.8.8.8', port=80): Max retries exceeded with url: /Uploads//.ad185973674f3bc1f3f8548e4bb5089b.php (Caused by ConnectTimeoutError(<requests.packages.urllib3.connection.HTTPConnection object at 0x7f93814dd850>, 'Connection to 8.8.8.8 timed out. (connect timeout=2)')) with the script: sample
2017-12-01 18:05:52  [error] fail to attack: 1.121.1.222 with error: HTTPConnectionPool(host='1.121.1.222', port=81): Max retries exceeded with url: /Uploads//.7b07e07c3769f27d0ff6fc43abac61c3.php (Caused by ConnectTimeoutError(<requests.packages.urllib3.connection.HTTPConnection object at 0x7f93814c7310>, 'Connection to 1.121.1.222 timed out. (connect timeout=2)')) with the script: sample
2017-12-01 18:05:55  [success] success to check_shell success from 172.17.0.4:80 with the script:function.py check_shell
2017-12-01 18:05:55  [success] success to execution cmd from 172.17.0.4:80 with the script:sample.py
2017-12-01 18:05:56  [warning] fail to attack: 118.190.78.155:80 with error: check_shell failed with the script: function.py check_shell
2017-12-01 18:05:56  [warning] fail to attack: 118.190.78.155:80 with error: execution cmd failed with the script: sample.py
2017-12-01 18:05:58  [error] fail to attack: 8.8.8.8 with error: HTTPConnectionPool(host='8.8.8.8', port=80): Max retries exceeded with url: /Uploads//.ad185973674f3bc1f3f8548e4bb5089b.php (Caused by ConnectTimeoutError(<requests.packages.urllib3.connection.HTTPConnection object at 0x7f93814dd810>, 'Connection to 8.8.8.8 timed out. (connect timeout=2)')) with the script: sample
2017-12-01 18:07:22  [success] success to check_shell success from 172.17.0.4:80 with the script:function.py check_shell
2017-12-01 18:07:22  [success] success to get flag success from flag server with the script:flag.py post_flag
2017-12-01 18:07:22  [success] success to get flag success from 172.17.0.4:80 with the script:sample
2017-12-01 18:07:22  [warning] fail to attack: 118.190.78.155:80 with error: check_shell failed with the script: function.py check_shell
2017-12-01 18:07:22  [warning] fail to attack: 118.190.78.155:80 with error: flag format error,you may need to rewrite the shell with the script: sample.py attack
2017-12-01 18:07:24  [error] fail to attack: 8.8.8.8 with error: HTTPConnectionPool(host='8.8.8.8', port=80): Max retries exceeded with url: /Uploads//.ad185973674f3bc1f3f8548e4bb5089b.php (Caused by ConnectTimeoutError(<requests.packages.urllib3.connection.HTTPConnection object at 0x7fd55025d410>, 'Connection to 8.8.8.8 timed out. (connect timeout=2)')) with the script: sample
2017-12-01 18:07:26  [error] fail to attack: 1.121.1.222 with error: HTTPConnectionPool(host='1.121.1.222', port=81): Max retries exceeded with url: /Uploads//.7b07e07c3769f27d0ff6fc43abac61c3.php (Caused by ConnectTimeoutError(<requests.packages.urllib3.connection.HTTPConnection object at 0x7fd55022f290>, 'Connection to 1.121.1.222 timed out. (connect timeout=2)')) with the script: sample
2017-12-01 18:07:29  [success] success to check_shell success from 172.17.0.4:80 with the script:function.py check_shell
2017-12-01 18:07:29  [success] success to get flag success from flag server with the script:flag.py post_flag
2017-12-01 18:07:29  [success] success to get flag success from 172.17.0.4:80 with the script:sample
2017-12-01 18:07:29  [warning] fail to attack: 118.190.78.155:80 with error: check_shell failed with the script: function.py check_shell
2017-12-01 18:07:30  [warning] fail to attack: 118.190.78.155:80 with error: flag format error,you may need to rewrite the shell with the script: sample.py attack
2017-12-01 18:07:32  [error] fail to attack: 8.8.8.8 with error: HTTPConnectionPool(host='8.8.8.8', port=80): Max retries exceeded with url: /Uploads//.ad185973674f3bc1f3f8548e4bb5089b.php (Caused by ConnectTimeoutError(<requests.packages.urllib3.connection.HTTPConnection object at 0x7fd550245850>, 'Connection to 8.8.8.8 timed out. (connect timeout=2)')) with the script: sample
2017-12-01 18:07:34  [error] fail to attack: 1.121.1.222 with error: HTTPConnectionPool(host='1.121.1.222', port=81): Max retries exceeded with url: /Uploads//.7b07e07c3769f27d0ff6fc43abac61c3.php (Caused by ConnectTimeoutError(<requests.packages.urllib3.connection.HTTPConnection object at 0x7fd55022f310>, 'Connection to 1.121.1.222 timed out. (connect timeout=2)')) with the script: sample
2017-12-01 18:07:37  [success] success to check_shell success from 172.17.0.4:80 with the script:function.py check_shell
2017-12-01 18:07:37  [success] success to get flag success from flag server with the script:flag.py post_flag
2017-12-01 18:07:37  [success] success to get flag success from 172.17.0.4:80 with the script:sample
2017-12-01 18:07:37  [warning] fail to attack: 118.190.78.155:80 with error: check_shell failed with the script: function.py check_shell
2017-12-01 18:07:37  [warning] fail to attack: 118.190.78.155:80 with error: flag format error,you may need to rewrite the shell with the script: sample.py attack
2017-12-01 18:07:39  [error] fail to attack: 8.8.8.8 with error: HTTPConnectionPool(host='8.8.8.8', port=80): Max retries exceeded with url: /Uploads//.ad185973674f3bc1f3f8548e4bb5089b.php (Caused by ConnectTimeoutError(<requests.packages.urllib3.connection.HTTPConnection object at 0x7fd550245810>, 'Connection to 8.8.8.8 timed out. (connect timeout=2)')) with the script: sample
2017-12-01 18:07:41  [error] fail to attack: 1.121.1.222 with error: HTTPConnectionPool(host='1.121.1.222', port=81): Max retries exceeded with url: /Uploads//.7b07e07c3769f27d0ff6fc43abac61c3.php (Caused by ConnectTimeoutError(<requests.packages.urllib3.connection.HTTPConnection object at 0x7fd55022f350>, 'Connection to 1.121.1.222 timed out. (connect timeout=2)')) with the script: sample
2017-12-01 18:07:44  [success] success to check_shell success from 172.17.0.4:80 with the script:function.py check_shell
2017-12-01 18:07:44  [success] success to get flag success from flag server with the script:flag.py post_flag
2017-12-01 18:07:44  [success] success to get flag success from 172.17.0.4:80 with the script:sample
2017-12-01 18:07:44  [warning] fail to attack: 118.190.78.155:80 with error: check_shell failed with the script: function.py check_shell
2017-12-01 18:07:44  [warning] fail to attack: 118.190.78.155:80 with error: flag format error,you may need to rewrite the shell with the script: sample.py attack
2017-12-01 18:07:46  [error] fail to attack: 8.8.8.8 with error: HTTPConnectionPool(host='8.8.8.8', port=80): Max retries exceeded with url: /Uploads//.ad185973674f3bc1f3f8548e4bb5089b.php (Caused by ConnectTimeoutError(<requests.packages.urllib3.connection.HTTPConnection object at 0x7fd550224a90>, 'Connection to 8.8.8.8 timed out. (connect timeout=2)')) with the script: sample
2017-12-01 18:07:48  [error] fail to attack: 1.121.1.222 with error: HTTPConnectionPool(host='1.121.1.222', port=81): Max retries exceeded with url: /Uploads//.7b07e07c3769f27d0ff6fc43abac61c3.php (Caused by ConnectTimeoutError(<requests.packages.urllib3.connection.HTTPConnection object at 0x7fd55022f3d0>, 'Connection to 1.121.1.222 timed out. (connect timeout=2)')) with the script: sample
2017-12-01 18:13:38  [success] success to check_shell success from 172.17.0.4:80 with the script:function.py check_shell
2017-12-01 18:13:38  [success] success to get flag success from flag server with the script:flag.py post_flag
2017-12-01 18:13:38  [success] success to get flag success from 172.17.0.4:80 with the script:sample
2017-12-01 18:13:39  [warning] fail to attack: 118.190.78.155:80 with error: check_shell failed with the script: function.py check_shell
2017-12-01 18:13:39  [warning] fail to attack: 118.190.78.155:80 with error: flag format error,you may need to rewrite the shell with the script: sample.py attack
2017-12-01 18:13:41  [error] fail to attack: 8.8.8.8 with error: HTTPConnectionPool(host='8.8.8.8', port=80): Max retries exceeded with url: /Uploads//.ad185973674f3bc1f3f8548e4bb5089b.php (Caused by ConnectTimeoutError(<requests.packages.urllib3.connection.HTTPConnection object at 0x7f212def7fd0>, 'Connection to 8.8.8.8 timed out. (connect timeout=2)')) with the script: sample
2017-12-01 18:18:30  [success] success to check_shell success from 172.17.0.4:80 with the script:function.py check_shell
2017-12-01 18:18:30  [success] success to execution cmd from 172.17.0.4:80 with the script:sample.py
2017-12-01 18:18:30  [warning] fail to attack: 118.190.78.155:80 with error: check_shell failed with the script: function.py check_shell
2017-12-01 18:18:30  [warning] fail to attack: 118.190.78.155:80 with error: execution cmd failed with the script: sample.py
2017-12-01 18:18:32  [error] fail to attack: 8.8.8.8 with error: HTTPConnectionPool(host='8.8.8.8', port=80): Max retries exceeded with url: /Uploads//.ad185973674f3bc1f3f8548e4bb5089b.php (Caused by ConnectTimeoutError(<requests.packages.urllib3.connection.HTTPConnection object at 0x7f97d5ff5f90>, 'Connection to 8.8.8.8 timed out. (connect timeout=2)')) with the script: sample
2017-12-01 18:18:34  [error] fail to attack: 1.121.1.222 with error: HTTPConnectionPool(host='1.121.1.222', port=81): Max retries exceeded with url: /Uploads//.7b07e07c3769f27d0ff6fc43abac61c3.php (Caused by ConnectTimeoutError(<requests.packages.urllib3.connection.HTTPConnection object at 0x7f97d5fc9250>, 'Connection to 1.121.1.222 timed out. (connect timeout=2)')) with the script: sample
2017-12-01 18:19:08  [success] success to check_shell success from 172.17.0.4:80 with the script:function.py check_shell
2017-12-01 18:19:08  [success] success to execution cmd from 172.17.0.4:80 with the script:sample.py
2017-12-01 18:19:08  [warning] fail to attack: 118.190.78.155:80 with error: check_shell failed with the script: function.py check_shell
2017-12-01 18:19:08  [warning] fail to attack: 118.190.78.155:80 with error: execution cmd failed with the script: sample.py
2017-12-01 18:23:20  [success] success to check_shell success from 172.17.0.4:80 with the script:function.py check_shell
2017-12-01 18:23:20  [success] success to execution cmd from 172.17.0.4:80 with the script:sample.py
2017-12-01 18:23:20  [warning] fail to attack: 118.190.78.155:80 with error: check_shell failed with the script: function.py check_shell
2017-12-01 18:23:20  [warning] fail to attack: 118.190.78.155:80 with error: execution cmd failed with the script: sample.py
2017-12-01 18:23:22  [error] fail to attack: 8.8.8.8 with error: HTTPConnectionPool(host='8.8.8.8', port=80): Max retries exceeded with url: /Uploads//.ad185973674f3bc1f3f8548e4bb5089b.php (Caused by ConnectTimeoutError(<requests.packages.urllib3.connection.HTTPConnection object at 0x7f4ed8dd1f50>, 'Connection to 8.8.8.8 timed out. (connect timeout=2)')) with the script: sample
2017-12-01 18:23:24  [error] fail to attack: 1.121.1.222 with error: HTTPConnectionPool(host='1.121.1.222', port=81): Max retries exceeded with url: /Uploads//.7b07e07c3769f27d0ff6fc43abac61c3.php (Caused by ConnectTimeoutError(<requests.packages.urllib3.connection.HTTPConnection object at 0x7f4ed8da5310>, 'Connection to 1.121.1.222 timed out. (connect timeout=2)')) with the script: sample
2017-12-01 18:24:02  [success] success to check_shell success from 172.17.0.4:80 with the script:function.py check_shell
2017-12-01 18:24:02  [success] success to execution cmd from 172.17.0.4:80 with the script:sample.py
2017-12-01 18:24:02  [warning] fail to attack: 118.190.78.155:80 with error: check_shell failed with the script: function.py check_shell
2017-12-01 18:24:03  [warning] fail to attack: 118.190.78.155:80 with error: execution cmd failed with the script: sample.py
2017-12-01 18:24:05  [error] fail to attack: 8.8.8.8 with error: HTTPConnectionPool(host='8.8.8.8', port=80): Max retries exceeded with url: /Uploads//.ad185973674f3bc1f3f8548e4bb5089b.php (Caused by ConnectTimeoutError(<requests.packages.urllib3.connection.HTTPConnection object at 0x7f03aefc0f50>, 'Connection to 8.8.8.8 timed out. (connect timeout=2)')) with the script: sample
2017-12-01 18:24:07  [error] fail to attack: 1.121.1.222 with error: HTTPConnectionPool(host='1.121.1.222', port=81): Max retries exceeded with url: /Uploads//.7b07e07c3769f27d0ff6fc43abac61c3.php (Caused by ConnectTimeoutError(<requests.packages.urllib3.connection.HTTPConnection object at 0x7f03aef94310>, 'Connection to 1.121.1.222 timed out. (connect timeout=2)')) with the script: sample
2017-12-01 18:26:47  [success] success to check_shell success from 172.17.0.4:80 with the script:function.py check_shell
2017-12-01 18:26:47  [success] success to execution cmd from 172.17.0.4:80 with the script:sample.py
2017-12-01 18:26:47  [error] fail to attack: 118.190.78.155 with error: Header value 411 must be of type str or bytes, not <type 'int'> with the script: sample
2017-12-01 18:26:47  [error] fail to attack: 8.8.8.8 with error: Header value 411 must be of type str or bytes, not <type 'int'> with the script: sample
2017-12-01 18:26:47  [error] fail to attack: 1.121.1.222 with error: Header value 411 must be of type str or bytes, not <type 'int'> with the script: sample
2017-12-01 18:27:45  [success] success to check_shell success from 172.17.0.4:80 with the script:function.py check_shell
2017-12-01 18:27:45  [success] success to execution cmd from 172.17.0.4:80 with the script:sample.py
2017-12-01 18:27:45  [error] fail to attack: 118.190.78.155 with error: Header value 411 must be of type str or bytes, not <type 'int'> with the script: sample
2017-12-01 18:27:45  [error] fail to attack: 8.8.8.8 with error: Header value 411 must be of type str or bytes, not <type 'int'> with the script: sample
2017-12-01 18:27:45  [error] fail to attack: 1.121.1.222 with error: Header value 411 must be of type str or bytes, not <type 'int'> with the script: sample
2017-12-01 18:28:41  [success] success to check_shell success from 172.17.0.4:80 with the script:function.py check_shell
2017-12-01 18:28:41  [success] success to execution cmd from 172.17.0.4:80 with the script:sample.py
2017-12-01 18:28:41  [error] fail to attack: 118.190.78.155 with error: Header value 411 must be of type str or bytes, not <type 'int'> with the script: sample
2017-12-01 18:28:41  [error] fail to attack: 8.8.8.8 with error: Header value 411 must be of type str or bytes, not <type 'int'> with the script: sample
2017-12-01 18:28:41  [error] fail to attack: 1.121.1.222 with error: Header value 411 must be of type str or bytes, not <type 'int'> with the script: sample
2017-12-01 18:30:05  [success] success to check_shell success from 172.17.0.4:80 with the script:function.py check_shell
2017-12-01 18:30:05  [success] success to execution cmd from 172.17.0.4:80 with the script:sample.py
2017-12-01 18:30:07  [error] fail to attack: 118.190.78.155 with error: HTTPConnectionPool(host='118.190.78.155', port=80): Read timed out. (read timeout=2) with the script: sample
2017-12-01 18:30:09  [error] fail to attack: 8.8.8.8 with error: HTTPConnectionPool(host='8.8.8.8', port=80): Max retries exceeded with url: /Uploads//.ad185973674f3bc1f3f8548e4bb5089b.php (Caused by ConnectTimeoutError(<requests.packages.urllib3.connection.HTTPConnection object at 0x7f7499447310>, 'Connection to 8.8.8.8 timed out. (connect timeout=2)')) with the script: sample
2017-12-01 18:30:39  [success] success to check_shell success from 172.17.0.4:80 with the script:function.py check_shell
2017-12-01 18:30:39  [success] success to execution cmd from 172.17.0.4:80 with the script:sample.py
2017-12-01 18:30:41  [error] fail to attack: 118.190.78.155 with error: HTTPConnectionPool(host='118.190.78.155', port=80): Read timed out. (read timeout=2) with the script: sample
2017-12-01 18:30:43  [error] fail to attack: 8.8.8.8 with error: HTTPConnectionPool(host='8.8.8.8', port=80): Max retries exceeded with url: /Uploads//.ad185973674f3bc1f3f8548e4bb5089b.php (Caused by ConnectTimeoutError(<requests.packages.urllib3.connection.HTTPConnection object at 0x7fbd66117250>, 'Connection to 8.8.8.8 timed out. (connect timeout=2)')) with the script: sample
2017-12-01 18:30:45  [error] fail to attack: 1.121.1.222 with error: HTTPConnectionPool(host='1.121.1.222', port=81): Max retries exceeded with url: /Uploads//.7b07e07c3769f27d0ff6fc43abac61c3.php (Caused by ConnectTimeoutError(<requests.packages.urllib3.connection.HTTPConnection object at 0x7fbd66117310>, 'Connection to 1.121.1.222 timed out. (connect timeout=2)')) with the script: sample
2017-12-01 18:31:37  [success] success to check_shell success from 172.17.0.4:80 with the script:function.py check_shell
2017-12-01 18:31:37  [success] success to execution cmd from 172.17.0.4:80 with the script:sample.py
2017-12-01 18:31:39  [error] fail to attack: 118.190.78.155 with error: HTTPConnectionPool(host='118.190.78.155', port=80): Read timed out. (read timeout=2) with the script: sample
2017-12-01 18:34:14  [success] success to check_shell success from 172.17.0.4:80 with the script:function.py check_shell
2017-12-01 18:34:14  [success] success to execution cmd from 172.17.0.4:80 with the script:sample.py
2017-12-01 18:34:16  [error] fail to attack: 118.190.78.155 with error: HTTPConnectionPool(host='118.190.78.155', port=80): Read timed out. (read timeout=2) with the script: sample
2017-12-01 18:34:18  [error] fail to attack: 8.8.8.8 with error: HTTPConnectionPool(host='8.8.8.8', port=80): Max retries exceeded with url: /Uploads//.ad185973674f3bc1f3f8548e4bb5089b.php (Caused by ConnectTimeoutError(<requests.packages.urllib3.connection.HTTPConnection object at 0x7f9e63e17250>, 'Connection to 8.8.8.8 timed out. (connect timeout=2)')) with the script: sample
2017-12-01 18:36:45  [error] fail to attack: 172.17.0.4 with error: unhashable type: 'list' with the script: sample
2017-12-01 18:36:45  [error] fail to attack: 118.190.78.155 with error: unhashable type: 'list' with the script: sample
2017-12-01 18:36:45  [error] fail to attack: 8.8.8.8 with error: unhashable type: 'list' with the script: sample
2017-12-01 18:36:45  [error] fail to attack: 1.121.1.222 with error: unhashable type: 'list' with the script: sample
2017-12-01 18:41:25  [error] fail to attack: 172.17.0.4 with error: unhashable type: 'list' with the script: sample
2017-12-01 18:41:25  [error] fail to attack: 118.190.78.155 with error: unhashable type: 'list' with the script: sample
2017-12-01 18:41:25  [error] fail to attack: 8.8.8.8 with error: unhashable type: 'list' with the script: sample
2017-12-01 18:41:25  [error] fail to attack: 1.121.1.222 with error: unhashable type: 'list' with the script: sample
2017-12-01 18:43:49  [error] fail to attack: 172.17.0.4 with error: unhashable type: 'list' with the script: sample
2017-12-01 18:43:49  [error] fail to attack: 118.190.78.155 with error: unhashable type: 'list' with the script: sample
2017-12-01 18:43:49  [error] fail to attack: 8.8.8.8 with error: unhashable type: 'list' with the script: sample
2017-12-01 18:43:49  [error] fail to attack: 1.121.1.222 with error: unhashable type: 'list' with the script: sample
2017-12-01 18:44:28  [success] success to check_shell success from 172.17.0.4:80 with the script:function.py check_shell
2017-12-01 18:44:28  [success] success to execution cmd from 172.17.0.4:80 with the script:run.py
2017-12-01 18:44:28  [warning] fail to attack: 118.190.78.155:80 with error: check_shell failed with the script: function.py check_shell
2017-12-01 18:44:28  [warning] fail to attack: 118.190.78.155:80 with error: execution cmd failed with the script: run.py
2017-12-01 18:44:30  [error] fail to attack: 8.8.8.8 with error: HTTPConnectionPool(host='8.8.8.8', port=80): Max retries exceeded with url: /Uploads//.ad185973674f3bc1f3f8548e4bb5089b.php (Caused by ConnectTimeoutError(<requests.packages.urllib3.connection.HTTPConnection object at 0x7ff02353bfd0>, 'Connection to 8.8.8.8 timed out. (connect timeout=2)')) with the script: sample
2017-12-01 18:45:28  [success] success to check_shell success from 172.17.0.4:80 with the script:function.py check_shell
2017-12-01 18:45:28  [success] success to execution cmd from 172.17.0.4:80 with the script:run.py
2017-12-01 18:45:28  [warning] fail to attack: 118.190.78.155:80 with error: check_shell failed with the script: function.py check_shell
2017-12-01 18:45:29  [warning] fail to attack: 118.190.78.155:80 with error: execution cmd failed with the script: run.py
2017-12-01 18:45:31  [error] fail to attack: 8.8.8.8 with error: HTTPConnectionPool(host='8.8.8.8', port=80): Max retries exceeded with url: /Uploads//.ad185973674f3bc1f3f8548e4bb5089b.php (Caused by ConnectTimeoutError(<requests.packages.urllib3.connection.HTTPConnection object at 0x7f3d6053efd0>, 'Connection to 8.8.8.8 timed out. (connect timeout=2)')) with the script: sample
2017-12-01 18:45:33  [error] fail to attack: 1.121.1.222 with error: HTTPConnectionPool(host='1.121.1.222', port=81): Max retries exceeded with url: /Uploads//.7b07e07c3769f27d0ff6fc43abac61c3.php (Caused by ConnectTimeoutError(<requests.packages.urllib3.connection.HTTPConnection object at 0x7f3d60514290>, 'Connection to 1.121.1.222 timed out. (connect timeout=2)')) with the script: sample
2017-12-01 18:45:53  [success] success to check_shell success from 172.17.0.4:80 with the script:function.py check_shell
2017-12-01 18:45:53  [success] success to execution cmd from 172.17.0.4:80 with the script:run.py
2017-12-01 18:45:53  [warning] fail to attack: 118.190.78.155:80 with error: check_shell failed with the script: function.py check_shell
2017-12-01 18:45:53  [warning] fail to attack: 118.190.78.155:80 with error: execution cmd failed with the script: run.py
2017-12-01 18:52:53  [success] success to check_shell success from 172.17.0.4:80 with the script:function.py check_shell
2017-12-01 18:52:53  [success] success to execution cmd from 172.17.0.4:80 with the script:run.py
2017-12-01 18:52:53  [warning] fail to attack: 118.190.78.155:80 with error: check_shell failed with the script: function.py check_shell
2017-12-01 18:52:53  [warning] fail to attack: 118.190.78.155:80 with error: execution cmd failed with the script: run.py
2017-12-01 18:53:07  [success] success to check_shell success from 172.17.0.4:80 with the script:function.py check_shell
2017-12-01 18:53:07  [success] success to execution cmd from 172.17.0.4:80 with the script:run.py
2017-12-01 18:54:02  [success] success to check_shell success from 172.17.0.4:80 with the script:function.py check_shell
2017-12-01 18:54:02  [success] success to execution cmd from 172.17.0.4:80 with the script:run.py
2017-12-01 18:54:46  [success] success to check_shell success from 172.17.0.4:80 with the script:function.py check_shell
2017-12-01 18:54:46  [success] success to execution cmd from 172.17.0.4:80 with the script:run.py
2017-12-01 18:55:33  [success] success to check_shell success from 172.17.0.4:80 with the script:function.py check_shell
2017-12-01 18:55:33  [success] success to execution cmd from 172.17.0.4:80 with the script:run.py
2017-12-01 18:55:58  [success] success to check_shell success from 172.17.0.4:80 with the script:function.py check_shell
2017-12-01 18:55:58  [success] success to execution cmd from 172.17.0.4:80 with the script:run.py
2017-12-01 18:56:09  [success] success to check_shell success from 172.17.0.4:80 with the script:function.py check_shell
2017-12-01 18:56:09  [success] success to execution cmd from 172.17.0.4:80 with the script:run.py
2017-12-01 18:56:09  [warning] fail to attack: 118.190.78.155:80 with error: check_shell failed with the script: function.py check_shell
2017-12-01 18:56:09  [warning] fail to attack: 118.190.78.155:80 with error: execution cmd failed with the script: run.py
2017-12-01 18:56:11  [error] fail to attack: 8.8.8.8 with error: HTTPConnectionPool(host='8.8.8.8', port=80): Max retries exceeded with url: /Uploads//.ad185973674f3bc1f3f8548e4bb5089b.php (Caused by ConnectTimeoutError(<requests.packages.urllib3.connection.HTTPConnection object at 0x7f3ab6b2b710>, 'Connection to 8.8.8.8 timed out. (connect timeout=2)')) with the script: sample
2017-12-01 18:56:13  [error] fail to attack: 1.121.1.222 with error: HTTPConnectionPool(host='1.121.1.222', port=81): Max retries exceeded with url: /Uploads//.7b07e07c3769f27d0ff6fc43abac61c3.php (Caused by ConnectTimeoutError(<requests.packages.urllib3.connection.HTTPConnection object at 0x7f3ab6b002d0>, 'Connection to 1.121.1.222 timed out. (connect timeout=2)')) with the script: sample
2017-12-01 18:56:18  [success] success to check_shell success from 172.17.0.4:80 with the script:function.py check_shell
2017-12-01 18:56:18  [success] success to execution cmd from 172.17.0.4:80 with the script:run.py
2017-12-01 18:56:18  [warning] fail to attack: 118.190.78.155:80 with error: check_shell failed with the script: function.py check_shell
2017-12-01 18:56:18  [warning] fail to attack: 118.190.78.155:80 with error: execution cmd failed with the script: run.py
2017-12-01 18:56:20  [error] fail to attack: 8.8.8.8 with error: HTTPConnectionPool(host='8.8.8.8', port=80): Max retries exceeded with url: /Uploads//.ad185973674f3bc1f3f8548e4bb5089b.php (Caused by ConnectTimeoutError(<requests.packages.urllib3.connection.HTTPConnection object at 0x7f8f02b7f710>, 'Connection to 8.8.8.8 timed out. (connect timeout=2)')) with the script: sample
2017-12-01 18:56:22  [error] fail to attack: 1.121.1.222 with error: HTTPConnectionPool(host='1.121.1.222', port=81): Max retries exceeded with url: /Uploads//.7b07e07c3769f27d0ff6fc43abac61c3.php (Caused by ConnectTimeoutError(<requests.packages.urllib3.connection.HTTPConnection object at 0x7f8f02b542d0>, 'Connection to 1.121.1.222 timed out. (connect timeout=2)')) with the script: sample
2017-12-01 18:56:34  [success] success to check_shell success from 172.17.0.4:80 with the script:function.py check_shell
2017-12-01 18:56:34  [success] success to execution cmd from 172.17.0.4:80 with the script:run.py
2017-12-01 18:56:34  [warning] fail to attack: 118.190.78.155:80 with error: check_shell failed with the script: function.py check_shell
2017-12-01 18:56:34  [warning] fail to attack: 118.190.78.155:80 with error: execution cmd failed with the script: run.py
2017-12-01 18:56:36  [error] fail to attack: 8.8.8.8 with error: HTTPConnectionPool(host='8.8.8.8', port=80): Max retries exceeded with url: /Uploads//.ad185973674f3bc1f3f8548e4bb5089b.php (Caused by ConnectTimeoutError(<requests.packages.urllib3.connection.HTTPConnection object at 0x7fb00a414710>, 'Connection to 8.8.8.8 timed out. (connect timeout=2)')) with the script: sample
2017-12-01 18:56:38  [error] fail to attack: 1.121.1.222 with error: HTTPConnectionPool(host='1.121.1.222', port=81): Max retries exceeded with url: /Uploads//.7b07e07c3769f27d0ff6fc43abac61c3.php (Caused by ConnectTimeoutError(<requests.packages.urllib3.connection.HTTPConnection object at 0x7fb00a3e92d0>, 'Connection to 1.121.1.222 timed out. (connect timeout=2)')) with the script: sample
2017-12-01 18:56:41  [success] success to check_shell success from 172.17.0.4:80 with the script:function.py check_shell
2017-12-01 18:56:41  [success] success to execution cmd from 172.17.0.4:80 with the script:run.py
2017-12-01 18:56:41  [warning] fail to attack: 118.190.78.155:80 with error: check_shell failed with the script: function.py check_shell
2017-12-01 18:56:41  [warning] fail to attack: 118.190.78.155:80 with error: execution cmd failed with the script: run.py
2017-12-01 18:56:43  [error] fail to attack: 8.8.8.8 with error: HTTPConnectionPool(host='8.8.8.8', port=80): Max retries exceeded with url: /Uploads//.ad185973674f3bc1f3f8548e4bb5089b.php (Caused by ConnectTimeoutError(<requests.packages.urllib3.connection.HTTPConnection object at 0x7fb00a3fd590>, 'Connection to 8.8.8.8 timed out. (connect timeout=2)')) with the script: sample
2017-12-01 18:56:45  [error] fail to attack: 1.121.1.222 with error: HTTPConnectionPool(host='1.121.1.222', port=81): Max retries exceeded with url: /Uploads//.7b07e07c3769f27d0ff6fc43abac61c3.php (Caused by ConnectTimeoutError(<requests.packages.urllib3.connection.HTTPConnection object at 0x7fb00a3e9350>, 'Connection to 1.121.1.222 timed out. (connect timeout=2)')) with the script: sample
2017-12-01 18:57:05  [success] success to check_shell success from 172.17.0.4:80 with the script:function.py check_shell
2017-12-01 18:57:05  [success] success to execution cmd from 172.17.0.4:80 with the script:run.py
2017-12-01 18:57:05  [warning] fail to attack: 118.190.78.155:80 with error: check_shell failed with the script: function.py check_shell
2017-12-01 18:57:05  [warning] fail to attack: 118.190.78.155:80 with error: execution cmd failed with the script: run.py
2017-12-01 18:57:07  [error] fail to attack: 8.8.8.8 with error: HTTPConnectionPool(host='8.8.8.8', port=80): Max retries exceeded with url: /Uploads//.ad185973674f3bc1f3f8548e4bb5089b.php (Caused by ConnectTimeoutError(<requests.packages.urllib3.connection.HTTPConnection object at 0x7f70f45af710>, 'Connection to 8.8.8.8 timed out. (connect timeout=2)')) with the script: sample
2017-12-01 18:57:09  [error] fail to attack: 1.121.1.222 with error: HTTPConnectionPool(host='1.121.1.222', port=81): Max retries exceeded with url: /Uploads//.7b07e07c3769f27d0ff6fc43abac61c3.php (Caused by ConnectTimeoutError(<requests.packages.urllib3.connection.HTTPConnection object at 0x7f70f45842d0>, 'Connection to 1.121.1.222 timed out. (connect timeout=2)')) with the script: sample
2017-12-01 18:57:12  [success] success to check_shell success from 172.17.0.4:80 with the script:function.py check_shell
2017-12-01 18:57:12  [success] success to execution cmd from 172.17.0.4:80 with the script:run.py
2017-12-01 18:57:12  [warning] fail to attack: 118.190.78.155:80 with error: check_shell failed with the script: function.py check_shell
2017-12-01 18:57:12  [warning] fail to attack: 118.190.78.155:80 with error: execution cmd failed with the script: run.py
2017-12-01 18:57:14  [error] fail to attack: 8.8.8.8 with error: HTTPConnectionPool(host='8.8.8.8', port=80): Max retries exceeded with url: /Uploads//.ad185973674f3bc1f3f8548e4bb5089b.php (Caused by ConnectTimeoutError(<requests.packages.urllib3.connection.HTTPConnection object at 0x7f70f4598910>, 'Connection to 8.8.8.8 timed out. (connect timeout=2)')) with the script: sample
2017-12-01 18:57:16  [error] fail to attack: 1.121.1.222 with error: HTTPConnectionPool(host='1.121.1.222', port=81): Max retries exceeded with url: /Uploads//.7b07e07c3769f27d0ff6fc43abac61c3.php (Caused by ConnectTimeoutError(<requests.packages.urllib3.connection.HTTPConnection object at 0x7f70f4584350>, 'Connection to 1.121.1.222 timed out. (connect timeout=2)')) with the script: sample
2017-12-01 19:16:03  [success] success to check_shell success from 172.17.0.4:80 with the script:function.py check_shell
2017-12-01 19:16:03  [success] success to execution cmd from 172.17.0.4:80 with the script:run.py
2017-12-01 19:16:03  [warning] fail to attack: 118.190.78.155:80 with error: check_shell failed with the script: function.py check_shell
2017-12-01 19:16:04  [warning] fail to attack: 118.190.78.155:80 with error: execution cmd failed with the script: run.py
2017-12-01 19:16:06  [error] fail to attack: 8.8.8.8 with error: HTTPConnectionPool(host='8.8.8.8', port=80): Max retries exceeded with url: /Uploads//.ad185973674f3bc1f3f8548e4bb5089b.php (Caused by ConnectTimeoutError(<requests.packages.urllib3.connection.HTTPConnection object at 0x7f22ea898fd0>, 'Connection to 8.8.8.8 timed out. (connect timeout=2)')) with the script: sample
2017-12-01 19:16:08  [error] fail to attack: 1.121.1.222 with error: HTTPConnectionPool(host='1.121.1.222', port=81): Max retries exceeded with url: /Uploads//.7b07e07c3769f27d0ff6fc43abac61c3.php (Caused by ConnectTimeoutError(<requests.packages.urllib3.connection.HTTPConnection object at 0x7f22ea86f210>, 'Connection to 1.121.1.222 timed out. (connect timeout=2)')) with the script: sample
2017-12-01 19:16:11  [success] success to check_shell success from 172.17.0.4:80 with the script:function.py check_shell
2017-12-01 19:16:11  [success] success to execution cmd from 172.17.0.4:80 with the script:run.py
2017-12-01 19:16:11  [warning] fail to attack: 118.190.78.155:80 with error: check_shell failed with the script: function.py check_shell
2017-12-01 19:16:11  [warning] fail to attack: 118.190.78.155:80 with error: execution cmd failed with the script: run.py
2017-12-01 19:16:13  [error] fail to attack: 8.8.8.8 with error: HTTPConnectionPool(host='8.8.8.8', port=80): Max retries exceeded with url: /Uploads//.ad185973674f3bc1f3f8548e4bb5089b.php (Caused by ConnectTimeoutError(<requests.packages.urllib3.connection.HTTPConnection object at 0x7f22ea881510>, 'Connection to 8.8.8.8 timed out. (connect timeout=2)')) with the script: sample
2017-12-01 19:16:15  [error] fail to attack: 1.121.1.222 with error: HTTPConnectionPool(host='1.121.1.222', port=81): Max retries exceeded with url: /Uploads//.7b07e07c3769f27d0ff6fc43abac61c3.php (Caused by ConnectTimeoutError(<requests.packages.urllib3.connection.HTTPConnection object at 0x7f22ea86f290>, 'Connection to 1.121.1.222 timed out. (connect timeout=2)')) with the script: sample
2017-12-01 19:21:53  [success] success to check_shell success from 172.17.0.4:80 with the script:function.py check_shell
2017-12-01 19:21:53  [success] success to execution cmd from 172.17.0.4:80 with the script:run.py
2017-12-01 19:21:54  [warning] fail to attack: 118.190.78.155:80 with error: check_shell failed with the script: function.py check_shell
2017-12-01 19:21:54  [warning] fail to attack: 118.190.78.155:80 with error: execution cmd failed with the script: run.py
2017-12-01 19:21:56  [error] fail to attack: 8.8.8.8 with error: HTTPConnectionPool(host='8.8.8.8', port=80): Max retries exceeded with url: /Uploads//.ad185973674f3bc1f3f8548e4bb5089b.php (Caused by ConnectTimeoutError(<requests.packages.urllib3.connection.HTTPConnection object at 0x7f529ccc7fd0>, 'Connection to 8.8.8.8 timed out. (connect timeout=2)')) with the script: sample
2017-12-01 19:21:58  [error] fail to attack: 1.121.1.222 with error: HTTPConnectionPool(host='1.121.1.222', port=81): Max retries exceeded with url: /Uploads//.7b07e07c3769f27d0ff6fc43abac61c3.php (Caused by ConnectTimeoutError(<requests.packages.urllib3.connection.HTTPConnection object at 0x7f529cc9e250>, 'Connection to 1.121.1.222 timed out. (connect timeout=2)')) with the script: sample
2017-12-01 19:22:01  [success] success to check_shell success from 172.17.0.4:80 with the script:function.py check_shell
2017-12-01 19:22:01  [success] success to execution cmd from 172.17.0.4:80 with the script:run.py
2017-12-01 19:22:01  [warning] fail to attack: 118.190.78.155:80 with error: check_shell failed with the script: function.py check_shell
2017-12-01 19:22:01  [warning] fail to attack: 118.190.78.155:80 with error: execution cmd failed with the script: run.py
2017-12-01 19:22:03  [error] fail to attack: 8.8.8.8 with error: HTTPConnectionPool(host='8.8.8.8', port=80): Max retries exceeded with url: /Uploads//.ad185973674f3bc1f3f8548e4bb5089b.php (Caused by ConnectTimeoutError(<requests.packages.urllib3.connection.HTTPConnection object at 0x7f529ccaf710>, 'Connection to 8.8.8.8 timed out. (connect timeout=2)')) with the script: sample
2017-12-01 19:22:05  [error] fail to attack: 1.121.1.222 with error: HTTPConnectionPool(host='1.121.1.222', port=81): Max retries exceeded with url: /Uploads//.7b07e07c3769f27d0ff6fc43abac61c3.php (Caused by ConnectTimeoutError(<requests.packages.urllib3.connection.HTTPConnection object at 0x7f529cc9e2d0>, 'Connection to 1.121.1.222 timed out. (connect timeout=2)')) with the script: sample
2017-12-01 19:56:50  [success] success to check_shell success from 172.17.0.4:80 with the script:function.py check_shell
2017-12-01 19:56:50  [error] fail to attack: 172.17.0.4 with error: [Errno 2] No such file or directory: 'log/spec/172.17.0.4:80' with the script: sample
2017-12-01 19:56:50  [warning] fail to attack: 118.190.78.155:80 with error: check_shell failed with the script: function.py check_shell
2017-12-01 19:56:50  [error] fail to attack: 118.190.78.155 with error: [Errno 2] No such file or directory: 'log/spec/118.190.78.155:80' with the script: sample
2017-12-01 19:56:52  [error] fail to attack: 8.8.8.8 with error: HTTPConnectionPool(host='8.8.8.8', port=80): Max retries exceeded with url: /Uploads//.ad185973674f3bc1f3f8548e4bb5089b.php (Caused by ConnectTimeoutError(<requests.packages.urllib3.connection.HTTPConnection object at 0x7fc4aa37b050>, 'Connection to 8.8.8.8 timed out. (connect timeout=2)')) with the script: sample
2017-12-01 19:57:14  [success] success to check_shell success from 172.17.0.4:80 with the script:function.py check_shell
2017-12-01 19:57:14  [success] success to execution cmd from 172.17.0.4:80 with the script:run.py
2017-12-01 19:57:14  [warning] fail to attack: 118.190.78.155:80 with error: check_shell failed with the script: function.py check_shell
2017-12-01 19:57:14  [warning] fail to attack: 118.190.78.155:80 with error: execution cmd failed with the script: run.py
2017-12-01 19:57:14  [error] fail to attack: 118.190.78.155:80 with error: server is not vulnerable with the script: run.py
2017-12-01 19:57:16  [error] fail to attack: 8.8.8.8 with error: HTTPConnectionPool(host='8.8.8.8', port=80): Max retries exceeded with url: /Uploads//.ad185973674f3bc1f3f8548e4bb5089b.php (Caused by ConnectTimeoutError(<requests.packages.urllib3.connection.HTTPConnection object at 0x7f0d607dd350>, 'Connection to 8.8.8.8 timed out. (connect timeout=2)')) with the script: sample
2017-12-01 19:57:18  [error] fail to attack: 1.121.1.222 with error: HTTPConnectionPool(host='1.121.1.222', port=81): Max retries exceeded with url: /Uploads//.7b07e07c3769f27d0ff6fc43abac61c3.php (Caused by ConnectTimeoutError(<requests.packages.urllib3.connection.HTTPConnection object at 0x7f0d6079e510>, 'Connection to 1.121.1.222 timed out. (connect timeout=2)')) with the script: sample
2017-12-01 19:57:21  [success] success to check_shell success from 172.17.0.4:80 with the script:function.py check_shell
2017-12-01 19:57:21  [success] success to execution cmd from 172.17.0.4:80 with the script:run.py
2017-12-01 19:57:22  [warning] fail to attack: 118.190.78.155:80 with error: check_shell failed with the script: function.py check_shell
2017-12-01 19:57:22  [warning] fail to attack: 118.190.78.155:80 with error: execution cmd failed with the script: run.py
2017-12-01 19:57:22  [error] fail to attack: 118.190.78.155:80 with error: server is not vulnerable with the script: run.py
2017-12-01 19:57:24  [error] fail to attack: 8.8.8.8 with error: HTTPConnectionPool(host='8.8.8.8', port=80): Max retries exceeded with url: /Uploads//.ad185973674f3bc1f3f8548e4bb5089b.php (Caused by ConnectTimeoutError(<requests.packages.urllib3.connection.HTTPConnection object at 0x7f0d607ac810>, 'Connection to 8.8.8.8 timed out. (connect timeout=2)')) with the script: sample
2017-12-01 19:57:26  [error] fail to attack: 1.121.1.222 with error: HTTPConnectionPool(host='1.121.1.222', port=81): Max retries exceeded with url: /Uploads//.7b07e07c3769f27d0ff6fc43abac61c3.php (Caused by ConnectTimeoutError(<requests.packages.urllib3.connection.HTTPConnection object at 0x7f0d6079e590>, 'Connection to 1.121.1.222 timed out. (connect timeout=2)')) with the script: sample
2017-12-01 19:58:01  [success] success to check_shell success from 172.17.0.4:80 with the script:function.py check_shell
2017-12-01 19:58:01  [success] success to execution cmd from 172.17.0.4:80 with the script:run.py
2017-12-01 19:58:01  [warning] fail to attack: 118.190.78.155:80 with error: check_shell failed with the script: function.py check_shell
2017-12-01 19:58:02  [warning] fail to attack: 118.190.78.155:80 with error: execution cmd failed with the script: run.py
2017-12-01 19:58:02  [error] fail to attack: 118.190.78.155:80 with error: server is not vulnerable with the script: run.py
2017-12-01 19:58:04  [error] fail to attack: 8.8.8.8 with error: HTTPConnectionPool(host='8.8.8.8', port=80): Max retries exceeded with url: /Uploads//.ad185973674f3bc1f3f8548e4bb5089b.php (Caused by ConnectTimeoutError(<requests.packages.urllib3.connection.HTTPConnection object at 0x7f80c4f06350>, 'Connection to 8.8.8.8 timed out. (connect timeout=2)')) with the script: sample
2017-12-01 19:58:06  [error] fail to attack: 1.121.1.222 with error: HTTPConnectionPool(host='1.121.1.222', port=81): Max retries exceeded with url: /Uploads//.7b07e07c3769f27d0ff6fc43abac61c3.php (Caused by ConnectTimeoutError(<requests.packages.urllib3.connection.HTTPConnection object at 0x7f80c4ec7510>, 'Connection to 1.121.1.222 timed out. (connect timeout=2)')) with the script: sample
2017-12-01 19:58:26  [success] success to check_shell success from 172.17.0.4:80 with the script:function.py check_shell
2017-12-01 19:58:26  [success] success to execution cmd from 172.17.0.4:80 with the script:run.py
2017-12-01 19:58:26  [warning] fail to attack: 118.190.78.155:80 with error: check_shell failed with the script: function.py check_shell
2017-12-01 19:58:26  [warning] fail to attack: 118.190.78.155:80 with error: execution cmd failed with the script: run.py
2017-12-01 19:58:26  [error] fail to attack: 118.190.78.155:80 with error: server is not vulnerable with the script: run.py
2017-12-01 19:58:28  [error] fail to attack: 8.8.8.8 with error: HTTPConnectionPool(host='8.8.8.8', port=80): Max retries exceeded with url: /Uploads//.ad185973674f3bc1f3f8548e4bb5089b.php (Caused by ConnectTimeoutError(<requests.packages.urllib3.connection.HTTPConnection object at 0x7f80c4ed5810>, 'Connection to 8.8.8.8 timed out. (connect timeout=2)')) with the script: sample
2017-12-01 19:58:30  [error] fail to attack: 1.121.1.222 with error: HTTPConnectionPool(host='1.121.1.222', port=81): Max retries exceeded with url: /Uploads//.7b07e07c3769f27d0ff6fc43abac61c3.php (Caused by ConnectTimeoutError(<requests.packages.urllib3.connection.HTTPConnection object at 0x7f80c4ec7590>, 'Connection to 1.121.1.222 timed out. (connect timeout=2)')) with the script: sample
2017-12-01 19:59:37  [success] success to check_shell success from 172.17.0.4:80 with the script:function.py check_shell
2017-12-01 19:59:37  [success] success to execution cmd from 172.17.0.4:80 with the script:run.py
2017-12-01 19:59:38  [warning] fail to attack: 118.190.78.155:80 with error: check_shell failed with the script: function.py check_shell
2017-12-01 19:59:38  [warning] fail to attack: 118.190.78.155:80 with error: execution cmd failed with the script: run.py
2017-12-01 19:59:38  [error] fail to attack: 118.190.78.155:80 with error: server is not vulnerable with the script: run.py
2017-12-01 19:59:40  [error] fail to attack: 8.8.8.8 with error: HTTPConnectionPool(host='8.8.8.8', port=80): Max retries exceeded with url: /Uploads//.ad185973674f3bc1f3f8548e4bb5089b.php (Caused by ConnectTimeoutError(<requests.packages.urllib3.connection.HTTPConnection object at 0x7ffad3df6350>, 'Connection to 8.8.8.8 timed out. (connect timeout=2)')) with the script: sample
2017-12-01 19:59:42  [error] fail to attack: 1.121.1.222 with error: HTTPConnectionPool(host='1.121.1.222', port=81): Max retries exceeded with url: /Uploads//.7b07e07c3769f27d0ff6fc43abac61c3.php (Caused by ConnectTimeoutError(<requests.packages.urllib3.connection.HTTPConnection object at 0x7ffad3db7550>, 'Connection to 1.121.1.222 timed out. (connect timeout=2)')) with the script: sample
2017-12-01 19:59:57  [success] success to check_shell success from 172.17.0.4:80 with the script:function.py check_shell
2017-12-01 19:59:57  [success] success to execution cmd from 172.17.0.4:80 with the script:run.py
2017-12-01 19:59:57  [warning] fail to attack: 118.190.78.155:80 with error: check_shell failed with the script: function.py check_shell
2017-12-01 19:59:57  [warning] fail to attack: 118.190.78.155:80 with error: execution cmd failed with the script: run.py
2017-12-01 19:59:57  [error] fail to attack: 118.190.78.155:80 with error: server is not vulnerable with the script: run.py
2017-12-01 19:59:59  [error] fail to attack: 8.8.8.8 with error: HTTPConnectionPool(host='8.8.8.8', port=80): Max retries exceeded with url: /Uploads//.ad185973674f3bc1f3f8548e4bb5089b.php (Caused by ConnectTimeoutError(<requests.packages.urllib3.connection.HTTPConnection object at 0x7f984c113250>, 'Connection to 8.8.8.8 timed out. (connect timeout=2)')) with the script: sample
2017-12-01 20:00:01  [error] fail to attack: 1.121.1.222 with error: HTTPConnectionPool(host='1.121.1.222', port=81): Max retries exceeded with url: /Uploads//.7b07e07c3769f27d0ff6fc43abac61c3.php (Caused by ConnectTimeoutError(<requests.packages.urllib3.connection.HTTPConnection object at 0x7f984c0d7510>, 'Connection to 1.121.1.222 timed out. (connect timeout=2)')) with the script: sample
2017-12-01 20:00:21  [success] success to check_shell success from 172.17.0.4:80 with the script:function.py check_shell
2017-12-01 20:00:21  [success] success to execution cmd from 172.17.0.4:80 with the script:run.py
2017-12-01 20:00:21  [warning] fail to attack: 118.190.78.155:80 with error: check_shell failed with the script: function.py check_shell
2017-12-01 20:00:21  [warning] fail to attack: 118.190.78.155:80 with error: execution cmd failed with the script: run.py
2017-12-01 20:00:21  [error] fail to attack: 118.190.78.155:80 with error: server is not vulnerable with the script: run.py
2017-12-01 20:00:24  [error] fail to attack: 8.8.8.8 with error: HTTPConnectionPool(host='8.8.8.8', port=80): Max retries exceeded with url: /Uploads//.ad185973674f3bc1f3f8548e4bb5089b.php (Caused by ConnectTimeoutError(<requests.packages.urllib3.connection.HTTPConnection object at 0x7f984c0e6a90>, 'Connection to 8.8.8.8 timed out. (connect timeout=2)')) with the script: sample
2017-12-01 20:15:47  [success] success to check_shell success from 172.17.0.4:80 with the script:function.py check_shell
2017-12-01 20:15:47  [success] success to execution cmd from 172.17.0.4:80 with the script:run.py
2017-12-01 20:15:47  [success] success to check_shell success from 118.190.78.155:80 with the script:function.py check_shell
2017-12-01 20:15:49  [error] fail to attack: 118.190.78.155 with error: timed out with the script: function.py execute_shell
2017-12-01 20:15:49  [warning] fail to attack: 118.190.78.155:80 with error: execution cmd failed with the script: run.py
2017-12-01 20:15:49  [error] fail to attack: 118.190.78.155:80 with error: server is not vulnerable with the script: run.py
2017-12-01 20:15:51  [error] fail to attack: 8.8.8.8 with error: HTTPConnectionPool(host='8.8.8.8', port=80): Max retries exceeded with url: /Uploads//.ad185973674f3bc1f3f8548e4bb5089b.php (Caused by ConnectTimeoutError(<requests.packages.urllib3.connection.HTTPConnection object at 0x7f0a751ef510>, 'Connection to 8.8.8.8 timed out. (connect timeout=2)')) with the script: sample
2017-12-01 20:15:53  [error] fail to attack: 1.121.1.222 with error: HTTPConnectionPool(host='1.121.1.222', port=81): Max retries exceeded with url: /Uploads//.7b07e07c3769f27d0ff6fc43abac61c3.php (Caused by ConnectTimeoutError(<requests.packages.urllib3.connection.HTTPConnection object at 0x7f0a751b0510>, 'Connection to 1.121.1.222 timed out. (connect timeout=2)')) with the script: sample
2017-12-01 20:18:57  [success] success to check_shell success from 172.17.0.4:80 with the script:function.py check_shell
2017-12-01 20:18:57  [success] success to execution cmd from 172.17.0.4:80 with the script:run.py
2017-12-01 20:18:57  [success] success to check_shell success from 118.190.78.155:80 with the script:function.py check_shell
2017-12-01 20:18:59  [error] fail to attack: 118.190.78.155 with error: timed out with the script: function.py execute_shell
2017-12-01 20:18:59  [warning] fail to attack: 118.190.78.155:80 with error: execution cmd failed with the script: run.py
2017-12-01 20:18:59  [error] fail to attack: 118.190.78.155:80 with error: server is not vulnerable with the script: run.py
2017-12-01 20:19:01  [error] fail to attack: 8.8.8.8 with error: HTTPConnectionPool(host='8.8.8.8', port=80): Max retries exceeded with url: /Uploads//.ad185973674f3bc1f3f8548e4bb5089b.php (Caused by ConnectTimeoutError(<requests.packages.urllib3.connection.HTTPConnection object at 0x7f6b091ea510>, 'Connection to 8.8.8.8 timed out. (connect timeout=2)')) with the script: sample
2017-12-01 20:19:03  [error] fail to attack: 1.121.1.222 with error: HTTPConnectionPool(host='1.121.1.222', port=81): Max retries exceeded with url: /Uploads//.7b07e07c3769f27d0ff6fc43abac61c3.php (Caused by ConnectTimeoutError(<requests.packages.urllib3.connection.HTTPConnection object at 0x7f6b091ab510>, 'Connection to 1.121.1.222 timed out. (connect timeout=2)')) with the script: sample
2017-12-01 20:20:05  [success] success to check_shell success from 172.17.0.4:80 with the script:function.py check_shell
2017-12-01 20:20:05  [success] success to execution cmd from 172.17.0.4:80 with the script:run.py
2017-12-01 20:20:06  [success] success to check_shell success from 118.190.78.155:80 with the script:function.py check_shell
2017-12-01 20:20:08  [error] fail to attack: 118.190.78.155 with error: timed out with the script: function.py execute_shell
2017-12-01 20:20:08  [warning] fail to attack: 118.190.78.155:80 with error: execution cmd failed with the script: run.py
2017-12-01 20:20:08  [error] fail to attack: 118.190.78.155:80 with error: server is not vulnerable with the script: run.py
2017-12-01 20:20:10  [error] fail to attack: 8.8.8.8 with error: HTTPConnectionPool(host='8.8.8.8', port=80): Max retries exceeded with url: /Uploads//.ad185973674f3bc1f3f8548e4bb5089b.php (Caused by ConnectTimeoutError(<requests.packages.urllib3.connection.HTTPConnection object at 0x7f9d46bc2510>, 'Connection to 8.8.8.8 timed out. (connect timeout=2)')) with the script: sample
2017-12-01 20:20:12  [error] fail to attack: 1.121.1.222 with error: HTTPConnectionPool(host='1.121.1.222', port=81): Max retries exceeded with url: /Uploads//.7b07e07c3769f27d0ff6fc43abac61c3.php (Caused by ConnectTimeoutError(<requests.packages.urllib3.connection.HTTPConnection object at 0x7f9d46b83510>, 'Connection to 1.121.1.222 timed out. (connect timeout=2)')) with the script: sample
2017-12-01 20:20:44  [success] success to check_shell success from 172.17.0.4:80 with the script:function.py check_shell
2017-12-01 20:20:44  [success] success to execution cmd from 172.17.0.4:80 with the script:run.py
2017-12-01 20:20:44  [success] success to check_shell success from 118.190.78.155:80 with the script:function.py check_shell
2017-12-01 20:20:46  [error] fail to attack: 118.190.78.155 with error: timed out with the script: function.py execute_shell
2017-12-01 20:20:46  [warning] fail to attack: 118.190.78.155:80 with error: execution cmd failed with the script: run.py
2017-12-01 20:20:46  [error] fail to attack: 118.190.78.155:80 with error: server is not vulnerable with the script: run.py
2017-12-01 20:20:48  [error] fail to attack: 8.8.8.8 with error: HTTPConnectionPool(host='8.8.8.8', port=80): Max retries exceeded with url: /Uploads//.ad185973674f3bc1f3f8548e4bb5089b.php (Caused by ConnectTimeoutError(<requests.packages.urllib3.connection.HTTPConnection object at 0x7fc1a9783510>, 'Connection to 8.8.8.8 timed out. (connect timeout=2)')) with the script: sample
2017-12-01 20:20:50  [error] fail to attack: 1.121.1.222 with error: HTTPConnectionPool(host='1.121.1.222', port=81): Max retries exceeded with url: /Uploads//.7b07e07c3769f27d0ff6fc43abac61c3.php (Caused by ConnectTimeoutError(<requests.packages.urllib3.connection.HTTPConnection object at 0x7fc1a9744510>, 'Connection to 1.121.1.222 timed out. (connect timeout=2)')) with the script: sample
2017-12-01 20:21:10  [success] success to check_shell success from 172.17.0.4:80 with the script:function.py check_shell
2017-12-01 20:21:10  [success] success to execution cmd from 172.17.0.4:80 with the script:run.py
2017-12-01 20:21:10  [success] success to check_shell success from 118.190.78.155:80 with the script:function.py check_shell
2017-12-01 20:21:12  [error] fail to attack: 118.190.78.155 with error: timed out with the script: function.py execute_shell
2017-12-01 20:21:12  [warning] fail to attack: 118.190.78.155:80 with error: execution cmd failed with the script: run.py
2017-12-01 20:21:12  [error] fail to attack: 118.190.78.155:80 with error: server is not vulnerable with the script: run.py
2017-12-01 20:21:14  [error] fail to attack: 8.8.8.8 with error: HTTPConnectionPool(host='8.8.8.8', port=80): Max retries exceeded with url: /Uploads//.ad185973674f3bc1f3f8548e4bb5089b.php (Caused by ConnectTimeoutError(<requests.packages.urllib3.connection.HTTPConnection object at 0x7fc1a97579d0>, 'Connection to 8.8.8.8 timed out. (connect timeout=2)')) with the script: sample
2017-12-01 20:21:16  [error] fail to attack: 1.121.1.222 with error: HTTPConnectionPool(host='1.121.1.222', port=81): Max retries exceeded with url: /Uploads//.7b07e07c3769f27d0ff6fc43abac61c3.php (Caused by ConnectTimeoutError(<requests.packages.urllib3.connection.HTTPConnection object at 0x7fc1a9744590>, 'Connection to 1.121.1.222 timed out. (connect timeout=2)')) with the script: sample
2017-12-01 20:21:48  [success] success to check_shell success from 172.17.0.4:80 with the script:function.py check_shell
2017-12-01 20:21:48  [success] success to execution cmd from 172.17.0.4:80 with the script:run.py
2017-12-01 20:21:48  [success] success to check_shell success from 118.190.78.155:80 with the script:function.py check_shell
2017-12-01 20:21:50  [error] fail to attack: 118.190.78.155 with error: timed out with the script: function.py execute_shell
2017-12-01 20:21:50  [warning] fail to attack: 118.190.78.155:80 with error: execution cmd failed with the script: run.py
2017-12-01 20:21:50  [error] fail to attack: 118.190.78.155:80 with error: server is not vulnerable with the script: run.py
2017-12-01 20:21:52  [error] fail to attack: 8.8.8.8 with error: HTTPConnectionPool(host='8.8.8.8', port=80): Max retries exceeded with url: /Uploads//.ad185973674f3bc1f3f8548e4bb5089b.php (Caused by ConnectTimeoutError(<requests.packages.urllib3.connection.HTTPConnection object at 0x7f61838ff510>, 'Connection to 8.8.8.8 timed out. (connect timeout=2)')) with the script: sample
2017-12-01 20:21:54  [error] fail to attack: 1.121.1.222 with error: HTTPConnectionPool(host='1.121.1.222', port=81): Max retries exceeded with url: /Uploads//.7b07e07c3769f27d0ff6fc43abac61c3.php (Caused by ConnectTimeoutError(<requests.packages.urllib3.connection.HTTPConnection object at 0x7f61838c1510>, 'Connection to 1.121.1.222 timed out. (connect timeout=2)')) with the script: sample
2017-12-01 20:22:14  [success] success to check_shell success from 172.17.0.4:80 with the script:function.py check_shell
2017-12-01 20:22:14  [success] success to execution cmd from 172.17.0.4:80 with the script:run.py
2017-12-01 20:22:14  [success] success to check_shell success from 118.190.78.155:80 with the script:function.py check_shell
2017-12-01 20:22:14  [error] fail to attack: 118.190.78.155 with error: [Errno 4] Interrupted system call with the script: function.py execute_shell
2017-12-01 20:22:14  [warning] fail to attack: 118.190.78.155:80 with error: execution cmd failed with the script: run.py
2017-12-01 20:22:14  [error] fail to attack: 118.190.78.155:80 with error: server is not vulnerable with the script: run.py
2017-12-01 20:22:16  [error] fail to attack: 8.8.8.8 with error: HTTPConnectionPool(host='8.8.8.8', port=80): Max retries exceeded with url: /Uploads//.ad185973674f3bc1f3f8548e4bb5089b.php (Caused by ConnectTimeoutError(<requests.packages.urllib3.connection.HTTPConnection object at 0x7f61838d0790>, 'Connection to 8.8.8.8 timed out. (connect timeout=2)')) with the script: sample
2017-12-01 20:22:18  [error] fail to attack: 1.121.1.222 with error: HTTPConnectionPool(host='1.121.1.222', port=81): Max retries exceeded with url: /Uploads//.7b07e07c3769f27d0ff6fc43abac61c3.php (Caused by ConnectTimeoutError(<requests.packages.urllib3.connection.HTTPConnection object at 0x7f61838c1550>, 'Connection to 1.121.1.222 timed out. (connect timeout=2)')) with the script: sample
2017-12-01 21:37:35  [success] success to check_shell success from 172.17.0.4:80 with the script:function.py check_shell
2017-12-01 21:37:35  [success] success to execution cmd from 172.17.0.4:80 with the script:run.py
2017-12-01 21:37:36  [warning] fail to attack: 118.190.78.155:80 with error: check_shell failed with the script: function.py check_shell
2017-12-01 21:37:36  [warning] fail to attack: 118.190.78.155:80 with error: execution cmd failed with the script: run.py
2017-12-01 21:37:36  [error] fail to attack: 118.190.78.155:80 with error: server is not vulnerable with the script: run.py
2017-12-01 21:37:38  [error] fail to attack: 8.8.8.8 with error: HTTPConnectionPool(host='8.8.8.8', port=80): Max retries exceeded with url: /Uploads//.ad185973674f3bc1f3f8548e4bb5089b.php (Caused by ConnectTimeoutError(<requests.packages.urllib3.connection.HTTPConnection object at 0x7f160572a350>, 'Connection to 8.8.8.8 timed out. (connect timeout=2)')) with the script: sample
2017-12-01 21:37:40  [error] fail to attack: 1.121.1.222 with error: HTTPConnectionPool(host='1.121.1.222', port=81): Max retries exceeded with url: /Uploads//.7b07e07c3769f27d0ff6fc43abac61c3.php (Caused by ConnectTimeoutError(<requests.packages.urllib3.connection.HTTPConnection object at 0x7f16056ec510>, 'Connection to 1.121.1.222 timed out. (connect timeout=2)')) with the script: sample
2017-12-01 21:43:56  [success] success to check_shell success from 172.17.0.4:80 with the script:function.py check_shell
2017-12-01 21:43:56  [success] success to execution cmd from 172.17.0.4:80 with the script:run.py
2017-12-01 21:43:56  [success] success to check_shell success from 118.190.78.155:80 with the script:function.py check_shell
2017-12-01 21:43:58  [error] fail to attack: 118.190.78.155 with error: timed out with the script: function.py execute_shell
2017-12-01 21:43:58  [warning] fail to attack: 118.190.78.155:80 with error: execution cmd failed with the script: run.py
2017-12-01 21:43:58  [error] fail to attack: 118.190.78.155:80 with error: server is not vulnerable with the script: run.py
2017-12-01 21:44:00  [error] fail to attack: 8.8.8.8 with error: HTTPConnectionPool(host='8.8.8.8', port=80): Max retries exceeded with url: /Uploads//.ad185973674f3bc1f3f8548e4bb5089b.php (Caused by ConnectTimeoutError(<requests.packages.urllib3.connection.HTTPConnection object at 0x7fd67d2eb510>, 'Connection to 8.8.8.8 timed out. (connect timeout=2)')) with the script: sample
2017-12-01 21:44:02  [error] fail to attack: 1.121.1.222 with error: HTTPConnectionPool(host='1.121.1.222', port=81): Max retries exceeded with url: /Uploads//.7b07e07c3769f27d0ff6fc43abac61c3.php (Caused by ConnectTimeoutError(<requests.packages.urllib3.connection.HTTPConnection object at 0x7fd67d2ad510>, 'Connection to 1.121.1.222 timed out. (connect timeout=2)')) with the script: sample
2017-12-01 21:44:12  [success] success to check_shell success from 172.17.0.4:80 with the script:function.py check_shell
2017-12-01 21:44:12  [success] success to execution cmd from 172.17.0.4:80 with the script:run.py
2017-12-01 21:44:12  [success] success to check_shell success from 118.190.78.155:80 with the script:function.py check_shell
2017-12-01 21:44:14  [error] fail to attack: 118.190.78.155 with error: timed out with the script: function.py execute_shell
2017-12-01 21:44:14  [warning] fail to attack: 118.190.78.155:80 with error: execution cmd failed with the script: run.py
2017-12-01 21:44:14  [error] fail to attack: 118.190.78.155:80 with error: server is not vulnerable with the script: run.py
2017-12-01 21:44:16  [error] fail to attack: 8.8.8.8 with error: HTTPConnectionPool(host='8.8.8.8', port=80): Max retries exceeded with url: /Uploads//.ad185973674f3bc1f3f8548e4bb5089b.php (Caused by ConnectTimeoutError(<requests.packages.urllib3.connection.HTTPConnection object at 0x7fd67d2bc9d0>, 'Connection to 8.8.8.8 timed out. (connect timeout=2)')) with the script: sample
2017-12-01 21:44:18  [error] fail to attack: 1.121.1.222 with error: HTTPConnectionPool(host='1.121.1.222', port=81): Max retries exceeded with url: /Uploads//.7b07e07c3769f27d0ff6fc43abac61c3.php (Caused by ConnectTimeoutError(<requests.packages.urllib3.connection.HTTPConnection object at 0x7fd67d2ad590>, 'Connection to 1.121.1.222 timed out. (connect timeout=2)')) with the script: sample
2017-12-01 21:44:38  [success] success to check_shell success from 172.17.0.4:80 with the script:function.py check_shell
2017-12-01 21:44:38  [success] success to execution cmd from 172.17.0.4:80 with the script:run.py
2017-12-01 21:44:38  [success] success to check_shell success from 118.190.78.155:80 with the script:function.py check_shell
2017-12-01 21:44:40  [error] fail to attack: 118.190.78.155 with error: timed out with the script: function.py execute_shell
2017-12-01 21:44:40  [warning] fail to attack: 118.190.78.155:80 with error: execution cmd failed with the script: run.py
2017-12-01 21:44:40  [error] fail to attack: 118.190.78.155:80 with error: server is not vulnerable with the script: run.py
2017-12-01 21:44:42  [error] fail to attack: 8.8.8.8 with error: HTTPConnectionPool(host='8.8.8.8', port=80): Max retries exceeded with url: /Uploads//.ad185973674f3bc1f3f8548e4bb5089b.php (Caused by ConnectTimeoutError(<requests.packages.urllib3.connection.HTTPConnection object at 0x7fd67d2bcb10>, 'Connection to 8.8.8.8 timed out. (connect timeout=2)')) with the script: sample
2017-12-01 21:44:44  [error] fail to attack: 1.121.1.222 with error: HTTPConnectionPool(host='1.121.1.222', port=81): Max retries exceeded with url: /Uploads//.7b07e07c3769f27d0ff6fc43abac61c3.php (Caused by ConnectTimeoutError(<requests.packages.urllib3.connection.HTTPConnection object at 0x7fd67d2ad5d0>, 'Connection to 1.121.1.222 timed out. (connect timeout=2)')) with the script: sample
2017-12-01 21:45:04  [success] success to check_shell success from 172.17.0.4:80 with the script:function.py check_shell
2017-12-01 21:45:04  [success] success to execution cmd from 172.17.0.4:80 with the script:run.py
2017-12-01 21:45:05  [success] success to check_shell success from 118.190.78.155:80 with the script:function.py check_shell
2017-12-01 21:45:07  [error] fail to attack: 118.190.78.155 with error: timed out with the script: function.py execute_shell
2017-12-01 21:45:07  [warning] fail to attack: 118.190.78.155:80 with error: execution cmd failed with the script: run.py
2017-12-01 21:45:07  [error] fail to attack: 118.190.78.155:80 with error: server is not vulnerable with the script: run.py
2017-12-01 21:45:09  [error] fail to attack: 8.8.8.8 with error: HTTPConnectionPool(host='8.8.8.8', port=80): Max retries exceeded with url: /Uploads//.ad185973674f3bc1f3f8548e4bb5089b.php (Caused by ConnectTimeoutError(<requests.packages.urllib3.connection.HTTPConnection object at 0x7fd67d2bc8d0>, 'Connection to 8.8.8.8 timed out. (connect timeout=2)')) with the script: sample
2017-12-01 21:45:11  [error] fail to attack: 1.121.1.222 with error: HTTPConnectionPool(host='1.121.1.222', port=81): Max retries exceeded with url: /Uploads//.7b07e07c3769f27d0ff6fc43abac61c3.php (Caused by ConnectTimeoutError(<requests.packages.urllib3.connection.HTTPConnection object at 0x7fd67d2ad650>, 'Connection to 1.121.1.222 timed out. (connect timeout=2)')) with the script: sample
2017-12-01 21:47:03  [success] success to check_shell success from 172.17.0.4:80 with the script:function.py check_shell
2017-12-01 21:47:03  [success] success to execution cmd from 172.17.0.4:80 with the script:run.py
2017-12-01 21:47:04  [success] success to check_shell success from 118.190.78.155:80 with the script:function.py check_shell
2017-12-01 21:47:06  [error] fail to attack: 118.190.78.155 with error: timed out with the script: function.py execute_shell
2017-12-01 21:47:06  [warning] fail to attack: 118.190.78.155:80 with error: execution cmd failed with the script: run.py
2017-12-01 21:47:06  [error] fail to attack: 118.190.78.155:80 with error: server is not vulnerable with the script: run.py
2017-12-01 21:47:08  [error] fail to attack: 8.8.8.8 with error: HTTPConnectionPool(host='8.8.8.8', port=80): Max retries exceeded with url: /Uploads//.ad185973674f3bc1f3f8548e4bb5089b.php (Caused by ConnectTimeoutError(<requests.packages.urllib3.connection.HTTPConnection object at 0x7f7153070510>, 'Connection to 8.8.8.8 timed out. (connect timeout=2)')) with the script: sample
2017-12-01 21:47:30  [success] success to check_shell success from 118.190.78.155:80 with the script:function.py check_shell
2017-12-01 21:47:32  [error] fail to attack: 118.190.78.155 with error: timed out with the script: function.py execute_shell
2017-12-01 21:47:32  [warning] fail to attack: 118.190.78.155:80 with error: execution cmd failed with the script: run.py
2017-12-01 21:47:32  [error] fail to attack: 118.190.78.155:80 with error: server is not vulnerable with the script: run.py
2017-12-01 21:47:52  [success] success to check_shell success from 118.190.78.155:80 with the script:function.py check_shell
2017-12-01 21:47:54  [error] fail to attack: 118.190.78.155 with error: timed out with the script: function.py execute_shell
2017-12-01 21:47:54  [warning] fail to attack: 118.190.78.155:80 with error: execution cmd failed with the script: run.py
2017-12-01 21:47:54  [error] fail to attack: 118.190.78.155:80 with error: server is not vulnerable with the script: run.py
2017-12-01 21:48:14  [success] success to check_shell success from 118.190.78.155:80 with the script:function.py check_shell
2017-12-01 21:48:17  [error] fail to attack: 118.190.78.155 with error: timed out with the script: function.py execute_shell
2017-12-01 21:48:17  [warning] fail to attack: 118.190.78.155:80 with error: execution cmd failed with the script: run.py
2017-12-01 21:48:17  [error] fail to attack: 118.190.78.155:80 with error: server is not vulnerable with the script: run.py
2017-12-01 21:48:37  [success] success to check_shell success from 118.190.78.155:80 with the script:function.py check_shell
2017-12-01 21:48:39  [error] fail to attack: 118.190.78.155 with error: timed out with the script: function.py execute_shell
2017-12-01 21:48:39  [warning] fail to attack: 118.190.78.155:80 with error: execution cmd failed with the script: run.py
2017-12-01 21:48:39  [error] fail to attack: 118.190.78.155:80 with error: server is not vulnerable with the script: run.py
2017-12-01 21:48:59  [success] success to check_shell success from 118.190.78.155:80 with the script:function.py check_shell
2017-12-01 21:49:01  [error] fail to attack: 118.190.78.155 with error: timed out with the script: function.py execute_shell
2017-12-01 21:49:01  [warning] fail to attack: 118.190.78.155:80 with error: execution cmd failed with the script: run.py
2017-12-01 21:49:01  [error] fail to attack: 118.190.78.155:80 with error: server is not vulnerable with the script: run.py
2017-12-01 21:49:21  [success] success to check_shell success from 118.190.78.155:80 with the script:function.py check_shell
2017-12-01 21:49:23  [error] fail to attack: 118.190.78.155 with error: timed out with the script: function.py execute_shell
2017-12-01 21:49:23  [warning] fail to attack: 118.190.78.155:80 with error: execution cmd failed with the script: run.py
2017-12-01 21:49:23  [error] fail to attack: 118.190.78.155:80 with error: server is not vulnerable with the script: run.py
2017-12-01 22:00:09  [success] success to check_shell success from 118.190.78.155:80 with the script:function.py check_shell
2017-12-01 22:00:11  [error] fail to attack: 118.190.78.155 with error: timed out with the script: function.py execute_shell
2017-12-01 22:00:11  [warning] fail to attack: 118.190.78.155:80 with error: execution cmd failed with the script: run.py
2017-12-01 22:00:11  [error] fail to attack: 118.190.78.155:80 with error: server is not vulnerable with the script: run.py
2017-12-01 22:01:18  [success] success to check_shell success from 118.190.78.155:80 with the script:function.py check_shell
2017-12-01 22:01:27  [success] success to check_shell success from 118.190.78.155:80 with the script:function.py check_shell
2017-12-01 22:01:29  [error] fail to attack: 118.190.78.155 with error: timed out with the script: function.py execute_shell
2017-12-01 22:01:29  [warning] fail to attack: 118.190.78.155:80 with error: execution cmd failed with the script: run.py
2017-12-01 22:01:29  [error] fail to attack: 118.190.78.155:80 with error: server is not vulnerable with the script: run.py
2017-12-01 22:02:01  [success] success to check_shell success from 118.190.78.155:80 with the script:function.py check_shell
2017-12-01 22:02:03  [error] fail to attack: 118.190.78.155 with error: timed out with the script: function.py execute_shell
2017-12-01 22:02:03  [warning] fail to attack: 118.190.78.155:80 with error: execution cmd failed with the script: run.py
2017-12-01 22:02:03  [error] fail to attack: 118.190.78.155:80 with error: server is not vulnerable with the script: run.py
2017-12-01 22:04:16  [success] success to check_shell success from 118.190.78.155:80 with the script:function.py check_shell
2017-12-01 22:04:18  [error] fail to attack: 118.190.78.155 with error: timed out with the script: function.py execute_shell
2017-12-01 22:04:18  [warning] fail to attack: 118.190.78.155:80 with error: execution cmd failed with the script: run.py
2017-12-01 22:04:18  [error] fail to attack: 118.190.78.155:80 with error: server is not vulnerable with the script: run.py
2017-12-01 22:04:48  [success] success to check_shell success from 118.190.78.155:80 with the script:function.py check_shell
2017-12-01 22:04:50  [error] fail to attack: 118.190.78.155 with error: timed out with the script: function.py execute_shell
2017-12-01 22:04:50  [warning] fail to attack: 118.190.78.155:80 with error: execution cmd failed with the script: run.py
2017-12-01 22:04:50  [error] fail to attack: 118.190.78.155:80 with error: server is not vulnerable with the script: run.py
2017-12-01 22:05:22  [success] success to check_shell success from 118.190.78.155:80 with the script:function.py check_shell
2017-12-01 22:05:24  [error] fail to attack: 118.190.78.155 with error: timed out with the script: function.py execute_shell
2017-12-01 22:05:24  [warning] fail to attack: 118.190.78.155:80 with error: execution cmd failed with the script: run.py
2017-12-01 22:05:24  [error] fail to attack: 118.190.78.155:80 with error: server is not vulnerable with the script: run.py
2017-12-01 22:06:15  [success] success to check_shell success from 118.190.78.155:80 with the script:function.py check_shell
2017-12-01 22:06:17  [error] fail to attack: 118.190.78.155 with error: timed out with the script: function.py execute_shell
2017-12-01 22:06:17  [warning] fail to attack: 118.190.78.155:80 with error: execution cmd failed with the script: run.py
2017-12-01 22:06:17  [error] fail to attack: 118.190.78.155:80 with error: server is not vulnerable with the script: run.py
2017-12-01 22:07:45  [success] success to check_shell success from 118.190.78.155:80 with the script:function.py check_shell
2017-12-01 22:07:47  [error] fail to attack: 118.190.78.155 with error: timed out with the script: function.py execute_shell
2017-12-01 22:07:47  [warning] fail to attack: 118.190.78.155:80 with error: execution cmd failed with the script: run.py
2017-12-01 22:07:47  [error] fail to attack: 118.190.78.155:80 with error: server is not vulnerable with the script: run.py
2017-12-01 22:08:12  [success] success to check_shell success from 118.190.78.155:80 with the script:function.py check_shell
2017-12-01 22:08:14  [error] fail to attack: 118.190.78.155 with error: timed out with the script: function.py execute_shell
2017-12-01 22:08:14  [warning] fail to attack: 118.190.78.155:80 with error: execution cmd failed with the script: run.py
2017-12-01 22:08:14  [error] fail to attack: 118.190.78.155:80 with error: server is not vulnerable with the script: run.py
2017-12-01 22:13:56  [warning] fail to attack: 118.190.78.155:80 with error: check_shell failed with the script: function.py check_shell
2017-12-01 22:13:57  [warning] fail to attack: 118.190.78.155:80 with error: execution cmd failed with the script: run.py
2017-12-01 22:13:57  [error] fail to attack: 118.190.78.155:80 with error: server is not vulnerable with the script: run.py
2017-12-01 22:14:22  [warning] fail to attack: 118.190.78.155:80 with error: check_shell failed with the script: function.py check_shell
2017-12-01 22:14:23  [warning] fail to attack: 118.190.78.155:80 with error: execution cmd failed with the script: run.py
2017-12-01 22:14:23  [error] fail to attack: 118.190.78.155:80 with error: server is not vulnerable with the script: run.py
2017-12-01 22:15:40  [warning] fail to attack: 118.190.78.155:80 with error: check_shell failed with the script: function.py check_shell
2017-12-01 22:15:41  [warning] fail to attack: 118.190.78.155:80 with error: execution cmd failed with the script: run.py
2017-12-01 22:15:41  [error] fail to attack: 118.190.78.155:80 with error: server is not vulnerable with the script: run.py
2017-12-01 22:16:01  [warning] fail to attack: 118.190.78.155:80 with error: check_shell failed with the script: function.py check_shell
2017-12-01 22:16:02  [warning] fail to attack: 118.190.78.155:80 with error: execution cmd failed with the script: run.py
2017-12-01 22:16:02  [error] fail to attack: 118.190.78.155:80 with error: server is not vulnerable with the script: run.py
2017-12-01 22:16:22  [warning] fail to attack: 118.190.78.155:80 with error: check_shell failed with the script: function.py check_shell
2017-12-01 22:16:22  [warning] fail to attack: 118.190.78.155:80 with error: execution cmd failed with the script: run.py
2017-12-01 22:16:22  [error] fail to attack: 118.190.78.155:80 with error: server is not vulnerable with the script: run.py
2017-12-01 22:16:42  [warning] fail to attack: 118.190.78.155:80 with error: check_shell failed with the script: function.py check_shell
2017-12-01 22:16:42  [warning] fail to attack: 118.190.78.155:80 with error: execution cmd failed with the script: run.py
2017-12-01 22:16:42  [error] fail to attack: 118.190.78.155:80 with error: server is not vulnerable with the script: run.py
2017-12-01 22:17:02  [warning] fail to attack: 118.190.78.155:80 with error: check_shell failed with the script: function.py check_shell
2017-12-01 22:17:03  [warning] fail to attack: 118.190.78.155:80 with error: execution cmd failed with the script: run.py
2017-12-01 22:17:03  [error] fail to attack: 118.190.78.155:80 with error: server is not vulnerable with the script: run.py
2017-12-01 22:17:23  [warning] fail to attack: 118.190.78.155:80 with error: check_shell failed with the script: function.py check_shell
2017-12-01 22:17:23  [warning] fail to attack: 118.190.78.155:80 with error: execution cmd failed with the script: run.py
2017-12-01 22:17:23  [error] fail to attack: 118.190.78.155:80 with error: server is not vulnerable with the script: run.py
2017-12-01 22:17:43  [warning] fail to attack: 118.190.78.155:80 with error: check_shell failed with the script: function.py check_shell
2017-12-01 22:17:43  [warning] fail to attack: 118.190.78.155:80 with error: execution cmd failed with the script: run.py
2017-12-01 22:17:43  [error] fail to attack: 118.190.78.155:80 with error: server is not vulnerable with the script: run.py
2017-12-01 22:18:03  [warning] fail to attack: 118.190.78.155:80 with error: check_shell failed with the script: function.py check_shell
2017-12-01 22:18:04  [warning] fail to attack: 118.190.78.155:80 with error: execution cmd failed with the script: run.py
2017-12-01 22:18:04  [error] fail to attack: 118.190.78.155:80 with error: server is not vulnerable with the script: run.py
2017-12-01 22:18:24  [warning] fail to attack: 118.190.78.155:80 with error: check_shell failed with the script: function.py check_shell
2017-12-01 22:18:24  [warning] fail to attack: 118.190.78.155:80 with error: execution cmd failed with the script: run.py
2017-12-01 22:18:24  [error] fail to attack: 118.190.78.155:80 with error: server is not vulnerable with the script: run.py
